<!-- <mujoco model="ur5e scene">

  <include file="ur5e.xml"/>

  <statistic center="0.3 0 0.4" extent="0.8"/>

  <visual>
    <headlight diffuse="0.6 0.6 0.6" ambient="0.1 0.1 0.1" specular="0 0 0"/>
    <rgba haze="0.15 0.25 0.35 1"/>
    <global azimuth="120" elevation="-20"/>
  </visual>

  <asset>
    <texture type="skybox" builtin="gradient" rgb1="0.3 0.5 0.7" rgb2="0 0 0" width="512" height="3072"/>
    <texture type="2d" name="groundplane" builtin="checker" mark="edge" rgb1="0.2 0.3 0.4" rgb2="0.1 0.2 0.3"
      markrgb="0.8 0.8 0.8" width="300" height="300"/>
    <material name="groundplane" texture="groundplane" texuniform="true" texrepeat="5 5" reflectance="0.2"/>
  </asset>

  <worldbody>
    <light pos="0 0 1.5" dir="0 0 -1" directional="true"/>
    <geom name="floor" size="0 0 0.05" type="plane" material="groundplane"/>
  </worldbody>

</mujoco> -->

<mujoco model="ur5e scene">  <statistic center="0.3 0 0.4" extent="0.8"/>  <visual>
    <headlight diffuse="0.6 0.6 0.6" ambient="0.1 0.1 0.1" specular="0 0 0"/>
    <rgba haze="0.15 0.25 0.35 1"/>
    <global azimuth="120" elevation="-20"/>
  </visual>  <asset>
    <texture type="skybox" builtin="gradient" rgb1="0.3 0.5 0.7" rgb2="0 0 0" width="512" height="3072"/>
    <texture type="2d" name="groundplane" builtin="checker" mark="edge" rgb1="0.2 0.3 0.4" rgb2="0.1 0.2 0.3"
      markrgb="0.8 0.8 0.8" width="300" height="300"/>
    <material name="groundplane" texture="groundplane" texuniform="true" texrepeat="5 5" reflectance="0.2"/>        
        <mesh name="StudyTable" file="assets/table/StudyTable.stl" scale="0.01 0.01 0.01" />
        <mesh name="Drawer_Wood" file="assets/table/Drawer_Wood.stl" scale="0.01 0.01 0.01" />
        <mesh name="Drawer_Handle" file="assets/table/Drawer_Handle.stl" scale="0.01 0.01 0.01" />
        <mesh name="Slide_Wood" file="assets/table/Slide_Wood.stl" scale="0.01 0.01 0.01" />
        <mesh name="Slide_Handle" file="assets/table/Slide_Handle.stl" scale="0.01 0.01 0.01" />
  </asset>  <worldbody>
    <light pos="0 0 1.5" dir="0 0 -1" directional="true"/>
    <geom name="floor" size="0 0 0.05" type="plane" material="groundplane"/>
  </worldbody>    <!-- <compiler angle="radian" /> -->
    <!-- <size njmax="500" nconmax="100" /> -->    <worldbody>
        <geom pos="0 -0.4 -0.2" quat="0.707141 0.707073 0 0" type="mesh" rgba="0.5 0.4 0.3 1" mesh="StudyTable" />        
            <body name="DeskDrawer" pos="0 0 0">
            <inertial pos="0 0 0" mass="2.5" diaginertia="0.002 0.002 0.002" />
            <joint name="drawer_joint" pos="0 0 0" axis="0 1 0" type="slide" limited="true" range="0 0.4" />
            <geom pos="0 -0.35 0.455" quat="0.707141 0.707073 0 0" type="mesh" rgba="0.5 0.4 0.3 1" mesh="Drawer_Wood" />
            <geom pos="0 -0.35 0.455" quat="0.707141 0.707073 0 0" type="mesh" rgba="0.8 0.8 0.8 1" mesh="Drawer_Handle" />
        </body>
        <body name="DeskSlide" pos="0 0 0">
            <inertial pos="0 0 0" mass="2.5" diaginertia="0.002 0.002 0.002" />
            <joint name="slide_joint" pos="0 0 0" axis="1 0 0" type="slide" limited="true" range="-0.1 0.5" />
            <geom pos="-0.2 -0.36 0.75" quat="0.707141 0.707073 0 0" type="mesh" rgba="0.5 0.4 0.3 1" mesh="Slide_Wood" />
            <geom pos="-0.2 -0.36 0.75" quat="0.707141 0.707073 0 0" type="mesh" rgba="0.8 0.8 0.8 1" mesh="Slide_Handle" />
        </body>
        <body name="Button1" pos="0 0 0">
            <inertial pos="0 0 0" mass="0.01" diaginertia="0.001 0.001 0.001" />
            <joint name="button1_joint" pos="0 0 0" axis="0 0 1" type="slide" limited="true" range="-0.1 0" />
            <geom size="0.02 0.015" pos="0.45 -0.55 0.59" type="cylinder" rgba="0.5 0 0 1" />
        </body>
        <body name="Button2" pos="0 0 0">
            <inertial pos="0 0 0" mass="0.01" diaginertia="0.001 0.001 0.001" />
            <joint name="button2_joint" pos="0 0 0" axis="0 0 1" type="slide" limited="true" range="-0.1 0" />
            <geom size="0.02 0.015" pos="0.3 -0.55 0.59" type="cylinder" rgba="0 0.5 0 1" />
        </body>
        <body name="Button3" pos="0 0 0">
            <inertial pos="0 0 0" mass="0.01" diaginertia="0.001 0.001 0.001" />
            <joint name="button3_joint" pos="0 0 0" axis="0 0 1" type="slide" limited="true" range="-0.1 0" />
            <geom size="0.02 0.015" pos="0.3 -0.55 0.59" type="cylinder" rgba="0 0 0.5 1" />
        </body>
    </worldbody>
<!-- </mujoco> -->        <include file="ur5e.xml"/>