<mujoco model="ur3e">
    <compiler angle="radian" meshdir="assets/ur_3e_collision/" texturedir="assets/ur_3e_visual/" />
    <!-- <option collision="predefined" /> -->
    <option integrator="implicitfast"/>

    <default>
        <default class="ur3e">
        <material specular="0.5" shininess="0.25"/>
        <joint axis="0 1 0" range="-6.28319 6.28319" armature="0.1"/>
        <general gaintype="fixed" biastype="affine" ctrlrange="-6.2831 6.2831" gainprm="2000" biasprm="0 -2000 -400"
            forcerange="-150 150"/>
        <default class="size3">
            <default class="size3_limited">
            <joint range="-3.1415 3.1415"/>
            <general ctrlrange="-3.1415 3.1415"/>
            </default>
        </default>
        <default class="size1">
            <general gainprm="500" biasprm="0 -500 -100" forcerange="-28 28"/>
        </default>
        <default class="visual">
            <geom type="mesh" contype="0" conaffinity="0" group="2"/>
        </default>
        <default class="collision">
            <geom type="capsule" group="3"/>
            <default class="eef_collision">
            <geom type="cylinder"/>
            </default>
        </default>
        <site size="0.001" rgba="0.5 0.5 0.5 0.3" group="4"/>
        </default>
    </default>


    <asset>
        <material class="ur3e" name="black" rgba="0.033 0.033 0.033 1"/>
        <material class="ur3e" name="jointgray" rgba="0.278 0.278 0.278 1"/>
        <material class="ur3e" name="linkgray" rgba="0.82 0.82 0.82 1"/>
        <material class="ur3e" name="urblue" rgba="0.49 0.678 0.8 1"/>

        <mesh name="base"     file="base.stl" />
        <mesh name="shoulder" file="shoulder.stl" />
        <mesh name="upperarm" file="upperarm.stl" />
        <mesh name="forearm"  file="forearm.stl" />
        <mesh name="wrist1"   file="wrist1.stl" />
        <mesh name="wrist2"   file="wrist2.stl" />
        <mesh name="wrist3"   file="wrist3.stl" />
    </asset>
    <worldbody>
    <light name="spotlight" mode="targetbodycom" target="wrist_2_link" pos="0 -1 2"/>
    <body name="base" pos="0 0 0" quat="1 0 0 1" childclass="ur3e">
        <inertial mass="2.0" pos="0 0 0" diaginertia="0.00443333156 0.00443333156 0.0072"/>
        <geom type="mesh" contype="0" conaffinity="0" group="1" rgba="0.7 0.7 0.7 1" mesh="base" />
        <geom type="mesh" rgba="0.7 0.7 0.7 1" mesh="base" />
        <body name="shoulder_link" pos="0 0 0.152">
            <inertial pos="0 0 0" mass="2" diaginertia="0.00809316 0.00809316 0.005625" />
            <joint name="shoulder_pan_joint" pos="0 0 0" axis="0 0 1" range="-3.14159 3.14159" />
            <geom type="mesh" contype="0" conaffinity="0" group="1" rgba="0.033 0.033 0.033 1" mesh="shoulder" />
            <geom type="mesh" rgba="0.033 0.033 0.033 1" mesh="shoulder" />
            <body name="upper_arm_link" pos="0 0.12 0" quat="0.707107 0 0.707107 0">
                <inertial pos="0 0 0.122" mass="1.71" diaginertia="0.0217771 0.0217771 0.00961875" />
                <joint name="shoulder_lift_joint" pos="0 0 0" axis="0 1 0" limited="true" range="-3.14159 3.14159" />
                <geom type="mesh" contype="0" conaffinity="0" group="1" rgba="0.0 0.0 0.0 0" mesh="upperarm" />
                <geom type="mesh" rgba="0.7 0.7 0.7 1" mesh="upperarm" />
                <body name="forearm_link" pos="0 -0.093 0.244">
                    <inertial pos="0 0 0.1065" mass="0.63" diaginertia="0.00653562 0.00653562 0.00354375" />
                    <joint name="elbow_joint" pos="0 0 0" axis="0 1 0" limited="true" range="-3.14159 3.14159" />
                    <geom type="mesh" contype="0" conaffinity="0" group="1" rgba="0.7 0.7 0.7 1" mesh="forearm" />
                    <geom type="mesh" rgba="0.7 0.7 0.7 1" mesh="forearm" />
                    <body name="wrist_1_link" pos="0 0 0.213" quat="0.707107 0 0.707107 0">
                        <inertial pos="0 0 0" quat="0.5 0.5 -0.5 0.5" mass="0.4" diaginertia="0.00225 0.002085 0.002085" />
                        <joint name="wrist_1_joint" pos="0 0 0" axis="0 1 0" limited="true" range="-3.14159 3.14159" />
                        <geom type="mesh" contype="0" conaffinity="0" group="1" rgba="0.7 0.7 0.7 1" mesh="wrist1" />
                        <geom type="mesh" rgba="0.7 0.7 0.7 1" mesh="wrist1" />
                        <body name="wrist_2_link" pos="0 0.104 0">
                            <inertial pos="0 0 0" quat="0.5 0.5 -0.5 0.5" mass="0.4" diaginertia="0.00225 0.002085 0.002085" />
                            <joint name="wrist_2_joint" pos="0 0 0" axis="0 0 1" limited="true" range="-3.14159 3.14159" />
                            <geom type="mesh" contype="0" conaffinity="0" group="1" rgba="0.7 0.7 0.7 1" mesh="wrist2" />
                            <geom type="mesh" rgba="0.7 0.7 0.7 1" mesh="wrist2" />
                            <body name="wrist_3_link" pos="0 0 0.085">
                                <inertial pos="0 0.000233618 0" quat="0.5 0.5 -0.5 0.5" mass="0.1705" diaginertia="0.000991097 0.000918909 0.000912204" />
                                <joint name="wrist_3_joint" pos="0 0 0" axis="0 1 0" limited="true" range="-3.14159 3.14159" />
                                <geom type="mesh" contype="0" conaffinity="0" group="1" rgba="0.7 0.7 0.7 1" mesh="wrist3" />
                                <geom type="mesh" rgba="0.7 0.7 0.7 1" mesh="wrist3" />
                                <geom size="0.005 0.005 0.005" pos="0 0.082 0" quat="0.707107 0 0 0.707107" type="box" />
                            </body>
                        </body>
                    </body>
                </body>
            </body>
        </body>
      </body>
    </worldbody>
    <!-- Actuators -->
    <!-- <actuator>
      <motor name="shoulder_pan_motor"  joint="shoulder_pan_joint"  ctrllimited="true" ctrlrange="-330 330" />
      <motor name="shoulder_lift_motor" joint="shoulder_lift_joint" ctrllimited="true" ctrlrange="-330 330" />
      <motor name="elbow_motor"         joint="elbow_joint"         ctrllimited="true" ctrlrange="-150 150" />
      <motor name="wrist_1_motor"       joint="wrist_1_joint"       ctrllimited="true" ctrlrange="-54 54" />
      <motor name="wrist_2_motor"       joint="wrist_2_joint"       ctrllimited="true" ctrlrange="-54 54" />
      <motor name="wrist_3_motor"       joint="wrist_3_joint"       ctrllimited="true" ctrlrange="-54 54" />
    </actuator> -->
    <actuator>
        <general class="size3" name="shoulder_pan" joint="shoulder_pan_joint"/>
        <general class="size3" name="shoulder_lift" joint="shoulder_lift_joint"/>
        <general class="size3_limited" name="elbow" joint="elbow_joint"/>
        <general class="size1" name="wrist_1" joint="wrist_1_joint"/>
        <general class="size1" name="wrist_2" joint="wrist_2_joint"/>
        <general class="size1" name="wrist_3" joint="wrist_3_joint"/>
    </actuator>

    <compiler convexhull="false"/>
    <contact>
            <exclude name="exclude_1_body_0" body1="shoulder_link" body2="base"/>
            <!-- <exclude name="exclude_2_body_1" body1="wrist_3_link" body2="wrist_2_link"/> -->
    </contact>
       

    <!-- <keyframe>
        <key name="home" qpos="-1.5708 -1.5708 1.5708 -1.5708 -1.5708 0" ctrl="-1.5708 -1.5708 1.5708 -1.5708 -1.5708 0"/>
    </keyframe> -->

</mujoco>
